Workbook

Sheet Contents
B2: Factor Pages: | G2: Indices:
B4: c30 | C4: c105 | D4: c155 | E4: c205 | G4: Index of Integers
B5: c60 | C5: c110 | D5: c160 | E5: c210
B6: c65 | C6: c115 | D6: c165 | E6: c220 | G6: Index of Parameters
B7: c70 | C7: c120 | D7: c170 | E7: c230
B8: c75 | C8: c125 | D8: c175 | E8: c270 | G8: Index of Results
B9: c80 | C9: c130 | D9: c180 | E9: c310
B10: c85 | C10: c135 | D10: c185 | E10: c320 | G10: References
B11: c90 | C11: c140 | D11: c190
B12: c95 | C12: c145 | D12: c195
B13: c100 | C13: c150 | D13: c200

Sheet c30
B2: c30 | J2: Run
E3: Parameters | I3: Execution | J3: c30_1 | K3: c30_2 | L3: c30_3 | M3: c30_4 | N3: c30_5 | O3: Mean
B4: Prev | D4: Polynomial selection | E4: Primary: | G4: Job control: | I4: Size optimization | J4: 0 | K4: 0.01 | L4: 0 | M4: 0.03 | N4: 0.05 | O4: =AVERAGE(J4:N4) -> 0.018 | R4: =O4+O13 -> 0.088
E5: ad | G5: incr | H5: 20
B6: Contents | E6: - min: | F6: 0 | G6: ad
E7: - max: | F7: 1000 | G7: - range: | H7: 100
B8: Next | E8: P | F8: 272 | G8: threads
E9: sopteffort | F9: 0
B10: Index of Integers | E10: nq | F10: 3
E11: nrkeep | F11: 2
E12: degree | F12: 3
B13: Index of Parameters | E13: ropteffort | F13: 1 | I13: Root optimization | J13: 0.05 | K13: 0.05 | L13: 0.05 | M13: 0.1 | N13: 0.1 | O13: =AVERAGE(J13:N13) -> 0.07
I15: Generate factor base | J15: 0.01 | K15: 0.02 | L15: 0.02 | M15: 0.02 | N15: 0.02 | O15: =AVERAGE(J15:N15) -> 0.018
B16: Index of Results
I17: Generate free relations | J17: 0.08 | K17: 0.08 | L17: 0.08 | M17: 0.08 | N17: 0.08 | O17: =AVERAGE(J17:N17) -> 0.08
I21: MurphyE of poly found: | J21: 7.84e-05 | K21: 5.35e-05 | L21: 7.87e-05 | M21: 0.000108 | N21: 0.000122 | O21: =AVERAGE(J21:N21) -> 8.812e-05
J23: Run
E24: Parameters | I24: Execution | J24: c30_1 | K24: c30_2 | L24: c30_3 | M24: c30_4 | N24: c30_5 | O24: Mean
D25: Lattice Sieving | E25: Primary: | G25: Job control: | I25: Lattice Sieving | J25: 1.37 | K25: 1.32 | L25: 1.26 | M25: 1.44 | N25: 2.03 | O25: =AVERAGE(J25:N25) -> 1.484
E26: mfb0 | F26: 18 | G26: qmin | H26: 50000
E27: mfb1 | F27: 18 | G27: qrange | H27: 1000
E28: lambda0 | G28: threads
E29: lambda1 | G29: rels_wanted | H29: 30000
E30: ncurves0
E31: ncurves1
E32: sqside
E33: I | F33: 9
J36: Run
E37: Parameters | I37: Execution | J37: c30_1 | K37: c30_2 | L37: c30_3 | M37: c30_4 | N37: c30_5 | O37: Mean
D38: Filtering | E38: purge.keep | I38: Duplicate Removal, splitting pass: | J38: 0.08 | K38: 0.08 | L38: 0.09 | M38: 0.08 | N38: 0.2 | O38: =AVERAGE(J38:N38) -> 0.106
E39: add_ratio | I39: Duplicate Removal, removal pass: | J39: 0.19 | K39: 0.23 | L39: 0.2 | M39: 0.21 | N39: 0.39 | O39: =AVERAGE(J39:N39) -> 0.244
E40: maxlevel | I40: Singleton removal | J40: 0.55 | K40: 0.49 | L40: 0.58 | M40: 0.63 | N40: 0.97 | O40: =AVERAGE(J40:N40) -> 0.644
E41: target_density | I41: Merging - merge | J41: 0.3 | K41: 0.04 | L41: 0.04 | M41: 0.03 | N41: 0.03 | O41: =AVERAGE(J41:N41) -> 0.088
E42: required_excess | I42: Merging - replay | J42: 0.02 | K42: 0.03 | L42: 0.02 | M42: 0.02 | N42: 0.01 | O42: =AVERAGE(J42:N42) -> 0.02
J45: Run
E46: Parameters | I46: Execution | J46: c30_1 | K46: c30_2 | L46: c30_3 | M46: c30_4 | N46: c30_5 | O46: Mean
D47: Linear Algebra | E47: Primary: | G47: Job control: | I47: Total | J47: 0.66 | K47: 0.59 | L47: 0.56 | M47: 0.53 | N47: 0.62 | O47: =AVERAGE(J47:N47) -> 0.592
E48: interval | G48: bwc.threads | I48: Quadratic | J48: 0.01 | K48: 0.02 | L48: 0.02 | M48: 0.03 | N48: 0.02 | O48: =AVERAGE(J48:N48) -> 0.02
E49: interleaving | G49: characters.threads | I49: Square root | J49: 0.12 | K49: 0.12 | L49: 0.19 | M49: 0.1 | N49: 0.1 | O49: =AVERAGE(J49:N49) -> 0.126
E50: m | F50: 64
...

Sheet c60
B2: c60 | J2: Run
E3: Parameters | I3: Execution | J3: c60_1 | K3: c60_2 | L3: c60_3 | M3: c60_4 | N3: c60_5 | O3: Mean
B4: Prev | D4: Polynomial selection | E4: Primary: | G4: Job control: | I4: Size optimization | J4: 0.94 | K4: 0.93 | L4: 0.98 | M4: 0.97 | N4: 1.03 | O4: =AVERAGE(J4:N4) -> 0.97 | R4: =O4+O13 -> 7.188
E5: ad | G5: incr | H5: 60
B6: Contents | E6: - min: | F6: 0 | G6: ad
E7: - max: | F7: 10000 | G7: - range: | H7: 5000
B8: Next | E8: P | F8: 420 | G8: threads
E9: sopteffort | F9: 0
B10: Index of Integers | E10: nq | F10: 64
E11: nrkeep | F11: 10
E12: degree | F12: 4
B13: Index of Parameters | E13: ropteffort | F13: 0.1 | I13: Root optimization | J13: 6.09 | K13: 6.42 | L13: 5.94 | M13: 6.36 | N13: 6.28 | O13: =AVERAGE(J13:N13) -> 6.218
I15: Generate factor base | J15: 0.1 | K15: 0.09 | L15: 0.09 | M15: 0.09 | N15: 0.09 | O15: =AVERAGE(J15:N15) -> 0.092
B16: Index of Results
I17: Generate free relations | J17: 0.38 | K17: 0.39 | L17: 0.38 | M17: 0.39 | N17: 0.38 | O17: =AVERAGE(J17:N17) -> 0.384
I21: MurphyE of poly found: | J21: 3.87e-07 | K21: 4.06e-07 | L21: 4.49e-07 | M21: 3.81e-07 | N21: 3.94e-07 | O21: =AVERAGE(J21:N21) -> 4.034e-07
J23: Run
E24: Parameters | I24: Execution | J24: c60_1 | K24: c60_2 | L24: c60_3 | M24: c60_4 | N24: c60_5 | O24: Mean
D25: Lattice Sieving | E25: Primary: | G25: Job control: | I25: Lattice Sieving | J25: 35.48 | K25: 32.93 | L25: 28.97 | M25: 32.46 | N25: 32.14 | O25: =AVERAGE(J25:N25) -> 32.396
E26: mfb0 | F26: 17 | G26: qmin | H26: 61961
E27: mfb1 | F27: 38 | G27: qrange | H27: 2000
E28: lambda0 | G28: threads
E29: lambda1
E30: ncurves0 | F30: 15
E31: ncurves1 | F31: 17
E32: sqside
E33: I | F33: 10
J36: Run
E37: Parameters | I37: Execution | J37: c60_1 | K37: c60_2 | L37: c60_3 | M37: c60_4 | N37: c60_5 | O37: Mean
D38: Filtering | E38: purge.keep | F38: 160 | I38: Duplicate Removal, splitting pass: | J38: 0.14 | K38: 0.13 | L38: 0.12 | M38: 0.14 | N38: 0.13 | O38: =AVERAGE(J38:N38) -> 0.132
E39: add_ratio | I39: Duplicate Removal, removal pass: | J39: 0.31 | K39: 0.37 | L39: 0.33 | M39: 0.3 | N39: 0.29 | O39: =AVERAGE(J39:N39) -> 0.32
E40: maxlevel | F40: 20 | I40: Singleton removal | J40: 0.65 | K40: 0.74 | L40: 0.49 | M40: 0.61 | N40: 0.47 | O40: =AVERAGE(J40:N40) -> 0.592
E41: target_density | F41: 170 | I41: Merging - merge | J41: 0.79 | K41: 0.73 | L41: 0.74 | M41: 0.75 | N41: 0.81 | O41: =AVERAGE(J41:N41) -> 0.764
E42: required_excess | I42: Merging - replay | J42: 0.18 | K42: 0.15 | L42: 0.17 | M42: 0.16 | N42: 0.17 | O42: =AVERAGE(J42:N42) -> 0.166
J45: Run
E46: Parameters | I46: Execution | J46: c60_1 | K46: c60_2 | L46: c60_3 | M46: c60_4 | N46: c60_5 | O46: Mean
D47: Linear Algebra | E47: Primary: | G47: Job control: | I47: Total | J47: 1.61 | K47: 1.38 | L47: 1.45 | M47: 1.56 | N47: 1.71 | O47: =AVERAGE(J47:N47) -> 1.542
E48: interval | F48: 100 | G48: bwc.threads | I48: Quadratic | J48: 0.16 | K48: 0.16 | L48: 0.16 | M48: 0.15 | N48: 0.17 | O48: =AVERAGE(J48:N48) -> 0.16
E49: interleaving | F49: 0 | G49: characters.threads | I49: Square root | J49: 0.85 | K49: 1.38 | L49: 0.49 | M49: 0.86 | N49: 0.55 | O49: =AVERAGE(J49:N49) -> 0.826
E50: m | F50: 64
...

Sheet c65
B2: c65 | J2: Run
E3: Parameters | I3: Execution | J3: c65_1 | K3: c65_2 | L3: c65_3 | M3: c65_4 | N3: c65_5 | O3: Mean
B4: Prev | D4: Polynomial selection | E4: Primary: | G4: Job control: | I4: Size optimization | J4: 2.03 | K4: 2.12 | L4: 1.86 | M4: 1.96 | N4: 1.94 | O4: =AVERAGE(J4:N4) -> 1.982 | R4: =O4+O13 -> 11.306
E5: ad | G5: incr | H5: 60
B6: Contents | E6: - min: | F6: 0 | G6: ad
E7: - max: | F7: 22000 | G7: - range: | H7: 11000
B8: Next | E8: P | F8: 950 | G8: threads
E9: sopteffort | F9: 0
B10: Index of Integers | E10: nq | F10: 64
E11: nrkeep | F11: 15
E12: degree | F12: 4
B13: Index of Parameters | E13: ropteffort | F13: 0.1 | I13: Root optimization | J13: 9.19 | K13: 9.25 | L13: 9.97 | M13: 9.85 | N13: 8.36 | O13: =AVERAGE(J13:N13) -> 9.324
I15: Generate factor base | J15: 0.19 | K15: 0.18 | L15: 0.2 | M15: 0.18 | N15: 0.19 | O15: =AVERAGE(J15:N15) -> 0.188
B16: Index of Results
I17: Generate free relations | J17: 0.76 | K17: 0.75 | L17: 0.73 | M17: 0.76 | N17: 0.75 | O17: =AVERAGE(J17:N17) -> 0.75
I21: MurphyE of poly found: | J21: 3.07e-07 | K21: 3.9e-07 | L21: 3.09e-07 | M21: 3.51e-07 | N21: 3.59e-07 | O21: =AVERAGE(J21:N21) -> 3.432e-07
J23: Run
E24: Parameters | I24: Execution | J24: c65_1 | K24: c65_2 | L24: c65_3 | M24: c65_4 | N24: c65_5 | O24: Mean
D25: Lattice Sieving | E25: Primary: | G25: Job control: | I25: Lattice Sieving | J25: 66.23 | K25: 59.61 | L25: 64.53 | M25: 60.17 | N25: 60.32 | O25: =AVERAGE(J25:N25) -> 62.172
E26: mfb0 | F26: 18 | G26: qmin | H26: 35979
E27: mfb1 | F27: 40 | G27: qrange | H27: 1000
E28: lambda0 | G28: threads
E29: lambda1
E30: ncurves0 | F30: 16
E31: ncurves1 | F31: 14
E32: sqside
E33: I | F33: 11
J36: Run
E37: Parameters | I37: Execution | J37: c65_1 | K37: c65_2 | L37: c65_3 | M37: c65_4 | N37: c65_5 | O37: Mean
D38: Filtering | E38: purge.keep | F38: 160 | I38: Duplicate Removal, splitting pass: | J38: 0.26 | K38: 0.24 | L38: 0.24 | M38: 0.27 | N38: 0.29 | O38: =AVERAGE(J38:N38) -> 0.26
E39: add_ratio | I39: Duplicate Removal, removal pass: | J39: 0.8 | K39: 0.62 | L39: 0.59 | M39: 0.59 | N39: 0.72 | O39: =AVERAGE(J39:N39) -> 0.664
E40: maxlevel | F40: 20 | I40: Singleton removal | J40: 1.25 | K40: 1.28 | L40: 1.25 | M40: 1.15 | N40: 1.27 | O40: =AVERAGE(J40:N40) -> 1.24
E41: target_density | F41: 170 | I41: Merging - merge | J41: 1.34 | K41: 1.39 | L41: 1.39 | M41: 1.48 | N41: 1.4 | O41: =AVERAGE(J41:N41) -> 1.4
E42: required_excess | I42: Merging - replay | J42: 0.27 | K42: 0.27 | L42: 0.28 | M42: 0.28 | N42: 0.28 | O42: =AVERAGE(J42:N42) -> 0.276
J45: Run
E46: Parameters | I46: Execution | J46: c65_1 | K46: c65_2 | L46: c65_3 | M46: c65_4 | N46: c65_5 | O46: Mean
D47: Linear Algebra | E47: Primary: | G47: Job control: | I47: Total | J47: 2.13 | K47: 2.09 | L47: 2.17 | M47: 2.31 | N47: 2.22 | O47: =AVERAGE(J47:N47) -> 2.184
E48: interval | F48: 100 | G48: bwc.threads | I48: Quadratic | J48: 0.25 | K48: 0.26 | L48: 0.25 | M48: 0.28 | N48: 0.27 | O48: =AVERAGE(J48:N48) -> 0.262
E49: interleaving | F49: 0 | G49: characters.threads | I49: Square root | J49: 0.79 | K49: 0.85 | L49: 2.04 | M49: 1.47 | N49: 0.83 | O49: =AVERAGE(J49:N49) -> 1.196
E50: m | F50: 64
...

Sheet c70
B2: c70 | J2: Run
E3: Parameters | I3: Execution | J3: c70_1 | K3: c70_2 | L3: c70_3 | M3: c70_4 | N3: c70_5 | O3: Mean
B4: Prev | D4: Polynomial selection | E4: Primary: | G4: Job control: | I4: Size optimization | J4: 3.76 | K4: 3.86 | L4: 3.77 | M4: 3.9 | N4: 3.98 | O4: =AVERAGE(J4:N4) -> 3.854 | R4: =O4+O13 -> 17.17
E5: ad | G5: incr | H5: 60
B6: Contents | E6: - min: | F6: 0 | G6: ad
E7: - max: | F7: 44000 | G7: - range: | H7: 22000
B8: Next | E8: P | F8: 1800 | G8: threads
E9: sopteffort | F9: 0
B10: Index of Integers | E10: nq | F10: 64
E11: nrkeep | F11: 20
E12: degree | F12: 4
B13: Index of Parameters | E13: ropteffort | F13: 0.1 | I13: Root optimization | J13: 13.84 | K13: 12.85 | L13: 13.4 | M13: 13.11 | N13: 13.38 | O13: =AVERAGE(J13:N13) -> 13.316
I15: Generate factor base | J15: 0.2 | K15: 0.2 | L15: 0.2 | M15: 0.2 | N15: 0.2 | O15: =AVERAGE(J15:N15) -> 0.2
B16: Index of Results
I17: Generate free relations | J17: 1.5 | K17: 1.49 | L17: 1.5 | M17: 1.5 | N17: 1.51 | O17: =AVERAGE(J17:N17) -> 1.5
I21: MurphyE of poly found: | J21: 1.6e-07 | K21: 1.65e-07 | L21: 1.58e-07 | M21: 1.99e-07 | N21: 2.39e-07 | O21: =AVERAGE(J21:N21) -> 1.842e-07
J23: Run
E24: Parameters | I24: Execution | J24: c70_1 | K24: c70_2 | L24: c70_3 | M24: c70_4 | N24: c70_5 | O24: Mean
D25: Lattice Sieving | E25: Primary: | G25: Job control: | I25: Lattice Sieving | J25: 100.12 | K25: 106.85 | L25: 113.37 | M25: 91.85 | N25: 86.77 | O25: =AVERAGE(J25:N25) -> 99.792
E26: mfb0 | F26: 19 | G26: qmin | H26: 18640
E27: mfb1 | F27: 42 | G27: qrange | H27: 1000
E28: lambda0 | G28: threads
E29: lambda1
E30: ncurves0 | F30: 16
E31: ncurves1 | F31: 14
E32: sqside
E33: I | F33: 11
J36: Run
E37: Parameters | I37: Execution | J37: c70_1 | K37: c70_2 | L37: c70_3 | M37: c70_4 | N37: c70_5 | O37: Mean
D38: Filtering | E38: purge.keep | F38: 160 | I38: Duplicate Removal, splitting pass: | J38: 0.55 | K38: 1.3 | L38: 0.47 | M38: 0.39 | N38: 0.47 | O38: =AVERAGE(J38:N38) -> 0.636
E39: add_ratio | I39: Duplicate Removal, removal pass: | J39: 1.8 | K39: 1.07 | L39: 1.05 | M39: 1.17 | N39: 1.23 | O39: =AVERAGE(J39:N39) -> 1.264
E40: maxlevel | F40: 20 | I40: Singleton removal | J40: 1.17 | K40: 1.89 | L40: 1.83 | M40: 2.28 | N40: 2.43 | O40: =AVERAGE(J40:N40) -> 1.92
E41: target_density | F41: 170 | I41: Merging - merge | J41: 2.34 | K41: 2.6 | L41: 2.47 | M41: 2.24 | N41: 2.1 | O41: =AVERAGE(J41:N41) -> 2.35
E42: required_excess | I42: Merging - replay | J42: 0.42 | K42: 0.5 | L42: 0.48 | M42: 0.41 | N42: 0.41 | O42: =AVERAGE(J42:N42) -> 0.444
J45: Run
E46: Parameters | I46: Execution | J46: c70_1 | K46: c70_2 | L46: c70_3 | M46: c70_4 | N46: c70_5 | O46: Mean
D47: Linear Algebra | E47: Primary: | G47: Job control: | I47: Total | J47: 3.35 | K47: 3.84 | L47: 3.84 | M47: 3.2 | N47: 3.12 | O47: =AVERAGE(J47:N47) -> 3.47
E48: interval | F48: 100 | G48: bwc.threads | I48: Quadratic | J48: 0.4 | K48: 0.43 | L48: 0.42 | M48: 0.38 | N48: 0.35 | O48: =AVERAGE(J48:N48) -> 0.396
E49: interleaving | F49: 0 | G49: characters.threads | I49: Square root | J49: 1.35 | K49: 1.48 | L49: 1.58 | M49: 1.22 | N49: 1.22 | O49: =AVERAGE(J49:N49) -> 1.37
E50: m | F50: 64
...

Sheet c75
B2: c75 | J2: Run
E3: Parameters | I3: Execution | J3: c75_1 | K3: c75_2 | L3: c75_3 | M3: c75_4 | N3: c75_5 | O3: Mean
B4: Prev | D4: Polynomial selection | E4: Primary: | G4: Job control: | I4: Size optimization | J4: 7.99 | K4: 8 | L4: 8.31 | M4: 7.74 | N4: 8.02 | O4: =AVERAGE(J4:N4) -> 8.012 | R4: =O4+O13 -> 27.672
E5: ad | G5: incr | H5: 60
B6: Contents | E6: - min: | F6: 0 | G6: ad
E7: - max: | F7: 84000 | G7: - range: | H7: 42000
B8: Next | E8: P | F8: 3600 | G8: threads
E9: sopteffort | F9: 0
B10: Index of Integers | E10: nq | F10: 64
E11: nrkeep | F11: 30
E12: degree | F12: 4
B13: Index of Parameters | E13: ropteffort | I13: Root optimization | J13: 19.6 | K13: 20.13 | L13: 20.67 | M13: 19.15 | N13: 18.75 | O13: =AVERAGE(J13:N13) -> 19.66
I15: Generate factor base | J15: 0.23 | K15: 0.23 | L15: 0.24 | M15: 0.25 | N15: 0.23 | O15: =AVERAGE(J15:N15) -> 0.236
B16: Index of Results
I17: Generate free relations | J17: 1.54 | K17: 1.53 | L17: 1.52 | M17: 1.52 | N17: 1.5 | O17: =AVERAGE(J17:N17) -> 1.522
I21: MurphyE of poly found: | J21: 6.06e-08 | K21: 5.68e-08 | L21: 5.56e-08 | M21: 6.22e-08 | N21: 6.04e-08 | O21: =AVERAGE(J21:N21) -> 5.912e-08
J23: Run
E24: Parameters | I24: Execution | J24: c75_1 | K24: c75_2 | L24: c75_3 | M24: c75_4 | N24: c75_5 | O24: Mean
D25: Lattice Sieving | E25: Primary: | G25: Job control: | I25: Lattice Sieving | J25: 214.69 | K25: 223.8 | L25: 203.38 | M25: 223.29 | N25: 206.49 | O25: =AVERAGE(J25:N25) -> 214.33
E26: mfb0 | F26: 41 | G26: qmin | H26: 100846
E27: mfb1 | F27: 42 | G27: qrange | H27: 1000
E28: lambda0 | G28: threads
E29: lambda1
E30: ncurves0 | F30: 25
E31: ncurves1 | F31: 19
E32: sqside
E33: I | F33: 11
J36: Run
E37: Parameters | I37: Execution | J37: c75_1 | K37: c75_2 | L37: c75_3 | M37: c75_4 | N37: c75_5 | O37: Mean
D38: Filtering | E38: purge.keep | F38: 160 | I38: Duplicate Removal, splitting pass: | J38: 0.63 | K38: 0.54 | L38: 0.62 | M38: 0.63 | N38: 0.57 | O38: =AVERAGE(J38:N38) -> 0.598
E39: add_ratio | I39: Duplicate Removal, removal pass: | J39: 1.49 | K39: 1.65 | L39: 2.23 | M39: 2.4 | N39: 1.74 | O39: =AVERAGE(J39:N39) -> 1.902
E40: maxlevel | F40: 20 | I40: Singleton removal | J40: 1.41 | K40: 1.7 | L40: 1.62 | M40: 1.59 | N40: 1.71 | O40: =AVERAGE(J40:N40) -> 1.606
E41: target_density | F41: 170 | I41: Merging - merge | J41: 6.29 | K41: 6.11 | L41: 6.23 | M41: 6.49 | N41: 6.37 | O41: =AVERAGE(J41:N41) -> 6.298
E42: required_excess | I42: Merging - replay | J42: 1.06 | K42: 1.02 | L42: 0.98 | M42: 1.08 | N42: 1.06 | O42: =AVERAGE(J42:N42) -> 1.04
J45: Run
E46: Parameters | I46: Execution | J46: c75_1 | K46: c75_2 | L46: c75_3 | M46: c75_4 | N46: c75_5 | O46: Mean
D47: Linear Algebra | E47: Primary: | G47: Job control: | I47: Total | J47: 12.5 | K47: 12.38 | L47: 10.56 | M47: 12.61 | N47: 12.49 | O47: =AVERAGE(J47:N47) -> 12.108
E48: interval | F48: 100 | G48: bwc.threads | I48: Quadratic | J48: 0.94 | K48: 0.9 | L48: 0.87 | M48: 0.93 | N48: 0.91 | O48: =AVERAGE(J48:N48) -> 0.91
E49: interleaving | F49: 0 | G49: characters.threads | I49: Square root | J49: 8.92 | K49: 6.52 | L49: 3.57 | M49: 3.86 | N49: 3.29 | O49: =AVERAGE(J49:N49) -> 5.232
E50: m | F50: 64
...

Sheet c80
B2: c80 | J2: Run
E3: Parameters | I3: Execution | J3: c80_1 | K3: c80_2 | L3: c80_3 | M3: c80_4 | N3: c80_5 | O3: Mean
B4: Prev | D4: Polynomial selection | E4: Primary: | G4: Job control: | I4: Size optimization | J4: 6.09 | K4: 6.05 | L4: 6.05 | M4: 6.3 | N4: 6.12 | O4: =AVERAGE(J4:N4) -> 6.122 | R4: =O4+O13 -> 28.464
E5: ad | G5: incr | H5: 60
B6: Contents | E6: - min: | F6: 0 | G6: ad
E7: - max: | F7: 50000 | G7: - range: | H7: 5000
B8: Next | E8: P | F8: 10000 | G8: threads
E9: sopteffort | F9: 0
B10: Index of Integers | E10: nq | F10: 64
E11: nrkeep | F11: 20
E12: degree | F12: 4
B13: Index of Parameters | E13: ropteffort | F13: 0.1 | I13: Root optimization | J13: 21.36 | K13: 21.64 | L13: 23.61 | M13: 22.54 | N13: 22.56 | O13: =AVERAGE(J13:N13) -> 22.342
I15: Generate factor base | J15: 0.28 | K15: 0.28 | L15: 0.28 | M15: 0.27 | N15: 0.28 | O15: =AVERAGE(J15:N15) -> 0.278
B16: Index of Results
I17: Generate free relations | J17: 1.52 | K17: 1.52 | L17: 1.5 | M17: 1.52 | N17: 1.52 | O17: =AVERAGE(J17:N17) -> 1.516
I21: MurphyE of poly found: | J21: 3.49e-08 | K21: 3.35e-08 | L21: 3.7e-08 | M21: 3.28e-08 | N21: 3.75e-08 | O21: =AVERAGE(J21:N21) -> 3.514e-08
J23: Run
E24: Parameters | I24: Execution | J24: c80_1 | K24: c80_2 | L24: c80_3 | M24: c80_4 | N24: c80_5 | O24: Mean
D25: Lattice Sieving | E25: Primary: | G25: Job control: | I25: Lattice Sieving | J25: 484.59 | K25: 449.46 | L25: 429.96 | M25: 515.77 | N25: 415.55 | O25: =AVERAGE(J25:N25) -> 459.066
E26: mfb0 | F26: 41 | G26: qmin | H26: 66606
E27: mfb1 | F27: 42 | G27: qrange | H27: 5000
E28: lambda0 | G28: threads
E29: lambda1
E30: ncurves0 | F30: 8
E31: ncurves1 | F31: 8
E32: sqside
E33: I | F33: 11
J36: Run
E37: Parameters | I37: Execution | J37: c80_1 | K37: c80_2 | L37: c80_3 | M37: c80_4 | N37: c80_5 | O37: Mean
D38: Filtering | E38: purge.keep | F38: 160 | I38: Duplicate Removal, splitting pass: | J38: 0.72 | K38: 0.63 | L38: 0.71 | M38: 0.93 | N38: 0.64 | O38: =AVERAGE(J38:N38) -> 0.726
E39: add_ratio | I39: Duplicate Removal, removal pass: | J39: 2.86 | K39: 2.56 | L39: 2.82 | M39: 2.59 | N39: 2.73 | O39: =AVERAGE(J39:N39) -> 2.712
E40: maxlevel | F40: 20 | I40: Singleton removal | J40: 2.41 | K40: 2 | L40: 2.13 | M40: 2.86 | N40: 2.4 | O40: =AVERAGE(J40:N40) -> 2.36
E41: target_density | F41: 170 | I41: Merging - merge | J41: 8.01 | K41: 8.47 | L41: 8.42 | M41: 7.55 | N41: 8.12 | O41: =AVERAGE(J41:N41) -> 8.114
E42: required_excess | I42: Merging - replay | J42: 1.32 | K42: 1.35 | L42: 1.39 | M42: 1.25 | N42: 1.38 | O42: =AVERAGE(J42:N42) -> 1.338
J45: Run
E46: Parameters | I46: Execution | J46: c80_1 | K46: c80_2 | L46: c80_3 | M46: c80_4 | N46: c80_5 | O46: Mean
D47: Linear Algebra | E47: Primary: | G47: Job control: | I47: Total | J47: 19.73 | K47: 20.1 | L47: 19.91 | M47: 17.52 | N47: 19.59 | O47: =AVERAGE(J47:N47) -> 19.37
E48: interval | F48: 100 | G48: bwc.threads | I48: Quadratic | J48: 1.12 | K48: 1.16 | L48: 1.14 | M48: 1.04 | N48: 1.13 | O48: =AVERAGE(J48:N48) -> 1.118
E49: interleaving | F49: 0 | G49: characters.threads | I49: Square root | J49: 4.7 | K49: 4.64 | L49: 8.85 | M49: 3.96 | N49: 5.04 | O49: =AVERAGE(J49:N49) -> 5.438
E50: m | F50: 64
...

Sheet c85
B2: c85 | J2: Run
E3: Parameters | I3: Execution | J3: c85_1 | K3: c85_2 | L3: c85_3 | M3: c85_4 | N3: c85_5 | O3: Mean
B4: Prev | D4: Polynomial selection | E4: Primary: | G4: Job control: | I4: Size optimization | J4: 21.87 | K4: 21.71 | L4: 21.33 | M4: 21.8 | N4: 21.72 | O4: =AVERAGE(J4:N4) -> 21.686 | R4: =O4+O13 -> 56.008
E5: ad | G5: incr | H5: 60
B6: Contents | E6: - min: | F6: 0 | G6: ad
E7: - max: | F7: 50000 | G7: - range: | H7: 5000
B8: Next | E8: P | F8: 10000 | G8: threads
E9: sopteffort | F9: 0
B10: Index of Integers | E10: nq | F10: 256
E11: nrkeep | F11: 30
E12: degree | F12: 4
B13: Index of Parameters | E13: ropteffort | F13: 0.1 | I13: Root optimization | J13: 33.01 | K13: 34.81 | L13: 34.21 | M13: 35.58 | N13: 34 | O13: =AVERAGE(J13:N13) -> 34.322
I15: Generate factor base | J15: 0.45 | K15: 0.44 | L15: 0.44 | M15: 0.45 | N15: 0.44 | O15: =AVERAGE(J15:N15) -> 0.444
B16: Index of Results
I17: Generate free relations | J17: 3.02 | K17: 3.01 | L17: 3.03 | M17: 3.05 | N17: 3.04 | O17: =AVERAGE(J17:N17) -> 3.03
I21: MurphyE of poly found: | J21: 3.54e-08 | K21: 3.59e-08 | L21: 3.25e-08 | M21: 2.94e-08 | N21: 3.54e-08 | O21: =AVERAGE(J21:N21) -> 3.372e-08
J23: Run
E24: Parameters | I24: Execution | J24: c85_1 | K24: c85_2 | L24: c85_3 | M24: c85_4 | N24: c85_5 | O24: Mean
D25: Lattice Sieving | E25: Primary: | G25: Job control: | I25: Lattice Sieving | J25: 719.38 | K25: 787.29 | L25: 819.79 | M25: 909.13 | N25: 764.43 | O25: =AVERAGE(J25:N25) -> 800.004
E26: mfb0 | F26: 44 | G26: qmin | H26: 146453
E27: mfb1 | F27: 44 | G27: qrange | H27: 1000
E28: lambda0 | G28: threads
E29: lambda1
E30: ncurves0 | F30: 24
E31: ncurves1 | F31: 19
E32: sqside
E33: I | F33: 11
J36: Run
E37: Parameters | I37: Execution | J37: c85_1 | K37: c85_2 | L37: c85_3 | M37: c85_4 | N37: c85_5 | O37: Mean
D38: Filtering | E38: purge.keep | F38: 160 | I38: Duplicate Removal, splitting pass: | J38: 1.08 | K38: 1.3 | L38: 1.27 | M38: 1.2 | N38: 1.06 | O38: =AVERAGE(J38:N38) -> 1.182
E39: add_ratio | I39: Duplicate Removal, removal pass: | J39: 4.69 | K39: 5.39 | L39: 5.11 | M39: 5.46 | N39: 4.57 | O39: =AVERAGE(J39:N39) -> 5.044
E40: maxlevel | F40: 20 | I40: Singleton removal | J40: 3.77 | K40: 4.67 | L40: 3.98 | M40: 4.7 | N40: 3.88 | O40: =AVERAGE(J40:N40) -> 4.2
E41: target_density | F41: 170 | I41: Merging - merge | J41: 14.11 | K41: 14.28 | L41: 15.49 | M41: 14.32 | N41: 15.21 | O41: =AVERAGE(J41:N41) -> 14.682
E42: required_excess | I42: Merging - replay | J42: 2.15 | K42: 2.2 | L42: 2.35 | M42: 2.24 | N42: 2.31 | O42: =AVERAGE(J42:N42) -> 2.25
J45: Run
E46: Parameters | I46: Execution | J46: c85_1 | K46: c85_2 | L46: c85_3 | M46: c85_4 | N46: c85_5 | O46: Mean
D47: Linear Algebra | E47: Primary: | G47: Job control: | I47: Total | J47: 47.19 | K47: 49.26 | L47: 53.75 | M47: 53.64 | N47: 52.34 | O47: =AVERAGE(J47:N47) -> 51.236
E48: interval | F48: 100 | G48: bwc.threads | I48: Quadratic | J48: 1.86 | K48: 1.92 | L48: 2.01 | M48: 1.92 | N48: 1.99 | O48: =AVERAGE(J48:N48) -> 1.94
E49: interleaving | F49: 0 | G49: characters.threads | I49: Square root | J49: 8.03 | K49: 7.71 | L49: 9.39 | M49: 9.1 | N49: 9.13 | O49: =AVERAGE(J49:N49) -> 8.672
E50: m | F50: 64
...

Sheet c90
B2: c90 | J2: Run
E3: Parameters | I3: Execution | J3: c90_1 | K3: c90_2 | L3: c90_3 | M3: c90_4 | N3: c90_5 | O3: Mean
B4: Prev | D4: Polynomial selection | E4: Primary: | G4: Job control: | I4: Size optimization | J4: 66.22 | K4: 65.44 | L4: 65.27 | M4: 65.71 | N4: 65.67 | O4: =AVERAGE(J4:N4) -> 65.662 | R4: =O4+O13 -> 112.92
E5: ad | G5: incr | H5: 60
B6: Contents | E6: - min: | F6: 0 | G6: ad
E7: - max: | F7: 150000 | G7: - range: | H7: 5000
B8: Next | E8: P | F8: 10000 | G8: threads | H8: 2
E9: sopteffort | F9: 0
B10: Index of Integers | E10: nq | F10: 256
E11: nrkeep | F11: 40
E12: degree | F12: 4
B13: Index of Parameters | E13: ropteffort | F13: 0.1 | I13: Root optimization | J13: 46.84 | K13: 45 | L13: 46.27 | M13: 49.21 | N13: 48.97 | O13: =AVERAGE(J13:N13) -> 47.258
I15: Generate factor base | J15: 0.65 | K15: 0.67 | L15: 0.65 | M15: 0.66 | N15: 0.65 | O15: =AVERAGE(J15:N15) -> 0.656
B16: Index of Results
I17: Generate free relations | J17: 6.05 | K17: 6.06 | L17: 6.07 | M17: 6.05 | N17: 6.01 | O17: =AVERAGE(J17:N17) -> 6.048
I21: MurphyE of poly found: | J21: 2.12e-08 | K21: 2.1e-08 | L21: 1.87e-08 | M21: 2.04e-08 | N21: 1.91e-08 | O21: =AVERAGE(J21:N21) -> 2.008e-08
J23: Run
E24: Parameters | I24: Execution | J24: c90_1 | K24: c90_2 | L24: c90_3 | M24: c90_4 | N24: c90_5 | O24: Mean
D25: Lattice Sieving | E25: Primary: | G25: Job control: | I25: Lattice Sieving | J25: 1463.18 | K25: 1774.1 | L25: 1596.06 | M25: 1507.32 | N25: 1660.33 | O25: =AVERAGE(J25:N25) -> 1600.198
E26: mfb0 | F26: 46 | G26: qmin | H26: 200923
E27: mfb1 | F27: 46 | G27: qrange | H27: 10000
E28: lambda0 | G28: threads | H28: 2
E29: lambda1
E30: ncurves0 | F30: 9
E31: ncurves1 | F31: 10
E32: sqside | F32: 1
E33: I | F33: 11
J36: Run
E37: Parameters | I37: Execution | J37: c90_1 | K37: c90_2 | L37: c90_3 | M37: c90_4 | N37: c90_5 | O37: Mean
D38: Filtering | E38: purge.keep | F38: 160 | I38: Duplicate Removal, splitting pass: | J38: 2.08 | K38: 2.28 | L38: 3.09 | M38: 2.01 | N38: 2.55 | O38: =AVERAGE(J38:N38) -> 2.402
E39: add_ratio | F39: 0.1 | I39: Duplicate Removal, removal pass: | J39: 6.5 | K39: 8.84 | L39: 8.69 | M39: 6.74 | N39: 9.24 | O39: =AVERAGE(J39:N39) -> 8.002
E40: maxlevel | F40: 20 | I40: Singleton removal | J40: 4.03 | K40: 8.11 | L40: 7.66 | M40: 4.12 | N40: 7.01 | O40: =AVERAGE(J40:N40) -> 6.186
E41: target_density | F41: 170 | I41: Merging - merge | J41: 24.86 | K41: 19.66 | L41: 22.61 | M41: 31.35 | N41: 24.14 | O41: =AVERAGE(J41:N41) -> 24.524
E42: required_excess | F42: 0 | I42: Merging - replay | J42: 3.58 | K42: 3.02 | L42: 3.08 | M42: 3.94 | N42: 3.3 | O42: =AVERAGE(J42:N42) -> 3.384
J45: Run
E46: Parameters | I46: Execution | J46: c90_1 | K46: c90_2 | L46: c90_3 | M46: c90_4 | N46: c90_5 | O46: Mean
D47: Linear Algebra | E47: Primary: | G47: Job control: | I47: Total | J47: 106.51 | K47: 79.92 | L47: 78.17 | M47: 120.38 | N47: 87.95 | O47: =AVERAGE(J47:N47) -> 94.586
E48: interval | F48: 100 | G48: bwc.threads | I48: Quadratic | J48: 3.09 | K48: 2.56 | L48: 2.51 | M48: 3.3 | N48: 2.67 | O48: =AVERAGE(J48:N48) -> 2.826
E49: interleaving | F49: 0 | G49: characters.threads | H49: 2 | I49: Square root | J49: 27.02 | K49: 11.95 | L49: 11.8 | M49: 29.4 | N49: 12.15 | O49: =AVERAGE(J49:N49) -> 18.464
E50: m | F50: 64
...

Sheet c95
B2: c95 | J2: Run
E3: Parameters | I3: Execution | J3: c95_1 | K3: c95_2 | L3: c95_3 | M3: c95_4 | N3: c95_5 | O3: Mean
B4: Prev | D4: Polynomial selection | E4: Primary: | G4: Job control: | I4: Size optimization | J4: 65.55 | K4: 65.69 | L4: 66.3 | M4: 65.74 | N4: 65.8 | O4: =AVERAGE(J4:N4) -> 65.816 | R4: =O4+O13 -> 114.994
E5: ad | G5: incr | H5: 60
B6: Contents | E6: - min: | F6: 0 | G6: ad
E7: - max: | F7: 150000 | G7: - range: | H7: 10000
B8: Next | E8: P | F8: 10000 | G8: threads
E9: sopteffort | F9: 0
B10: Index of Integers | E10: nq | F10: 256
E11: nrkeep | F11: 40
E12: degree | F12: 4
B13: Index of Parameters | E13: ropteffort | F13: 0.2 | I13: Root optimization | J13: 51.27 | K13: 49.44 | L13: 49.43 | M13: 47.31 | N13: 48.44 | O13: =AVERAGE(J13:N13) -> 49.178
I15: Generate factor base | J15: 2.19 | K15: 2.17 | L15: 2.17 | M15: 2.15 | N15: 2.16 | O15: =AVERAGE(J15:N15) -> 2.168
B16: Index of Results
I17: Generate free relations | J17: 6.1 | K17: 6.06 | L17: 6.06 | M17: 6.06 | N17: 6.03 | O17: =AVERAGE(J17:N17) -> 6.062
I21: MurphyE of poly found: | J21: 3.8e-08 | K21: 3.89e-08 | L21: 3.81e-08 | M21: 3.98e-08 | N21: 2.89e-08 | O21: =AVERAGE(J21:N21) -> 3.674e-08
J23: Run
E24: Parameters | I24: Execution | J24: c95_1 | K24: c95_2 | L24: c95_3 | M24: c95_4 | N24: c95_5 | O24: Mean
D25: Lattice Sieving | E25: Primary: | G25: Job control: | I25: Lattice Sieving | J25: 3843.23 | K25: 4698.23 | L25: 4022.74 | M25: 4017.25 | N25: 5645.35 | O25: =AVERAGE(J25:N25) -> 4445.36
E26: mfb0 | F26: 22 | G26: qmin | H26: 52140
E27: mfb1 | F27: 45 | G27: qrange | H27: 2000
E28: lambda0 | G28: threads
E29: lambda1
E30: ncurves0 | F30: 2
E31: ncurves1 | F31: 13
E32: sqside
E33: I | F33: 13
J36: Run
E37: Parameters | I37: Execution | J37: c95_1 | K37: c95_2 | L37: c95_3 | M37: c95_4 | N37: c95_5 | O37: Mean
D38: Filtering | E38: purge.keep | F38: 160 | I38: Duplicate Removal, splitting pass: | J38: 1.98 | K38: 1.81 | L38: 1.89 | M38: 1.95 | N38: 1.9 | O38: =AVERAGE(J38:N38) -> 1.906
E39: add_ratio | I39: Duplicate Removal, removal pass: | J39: 7.34 | K39: 6.69 | L39: 6.71 | M39: 6.76 | N39: 6.63 | O39: =AVERAGE(J39:N39) -> 6.826
E40: maxlevel | F40: 20 | I40: Singleton removal | J40: 8.31 | K40: 5.57 | L40: 7.13 | M40: 7.24 | N40: 5.13 | O40: =AVERAGE(J40:N40) -> 6.676
E41: target_density | F41: 170 | I41: Merging - merge | J41: 25.65 | K41: 31.41 | L41: 26.92 | M41: 28.3 | N41: 35.82 | O41: =AVERAGE(J41:N41) -> 29.62
E42: required_excess | I42: Merging - replay | J42: 3.08 | K42: 3.69 | L42: 3.23 | M42: 3.37 | N42: 4.03 | O42: =AVERAGE(J42:N42) -> 3.48
J45: Run
E46: Parameters | I46: Execution | J46: c95_1 | K46: c95_2 | L46: c95_3 | M46: c95_4 | N46: c95_5 | O46: Mean
D47: Linear Algebra | E47: Primary: | G47: Job control: | I47: Total | J47: 86.04 | K47: 128.82 | L47: 97.17 | M47: 57.75 | N47: 150.08 | O47: =AVERAGE(J47:N47) -> 103.972
E48: interval | F48: 100 | G48: bwc.threads | I48: Quadratic | J48: 2.54 | K48: 3.08 | L48: 2.73 | M48: 2.71 | N48: 3.32 | O48: =AVERAGE(J48:N48) -> 2.876
E49: interleaving | F49: 0 | G49: characters.threads | I49: Square root | J49: 13.71 | K49: 14.55 | L49: 24.69 | M49: 13.78 | N49: 16.66 | O49: =AVERAGE(J49:N49) -> 16.678
E50: m | F50: 64
...

Sheet c100
B2: c100 | J2: Run
E3: Parameters | I3: Execution | J3: c100_1 | K3: c100_2 | L3: c100_3 | M3: c100_4 | N3: c100_5 | O3: Mean
B4: Prev | D4: Polynomial selection | E4: Primary: | G4: Job control: | I4: Size optimization | J4: 62.39 | K4: 62.82 | L4: 62.87 | M4: 62.85 | N4: 62.25 | O4: =AVERAGE(J4:N4) -> 62.636 | R4: =O4+O13 -> 135.854
E5: ad | G5: incr | H5: 60
B6: Contents | E6: - min: | F6: 0 | G6: ad
E7: - max: | F7: 500000 | G7: - range: | H7: 10000
B8: Next | E8: P | F8: 10000 | G8: threads
E9: sopteffort | F9: 0
B10: Index of Integers | E10: nq | F10: 64
E11: nrkeep | F11: 40
E12: degree | F12: 4
B13: Index of Parameters | E13: ropteffort | F13: 0.5 | I13: Root optimization | J13: 72.77 | K13: 73.75 | L13: 74.65 | M13: 70.38 | N13: 74.54 | O13: =AVERAGE(J13:N13) -> 73.218
I15: Generate factor base | J15: 0.83 | K15: 0.85 | L15: 0.85 | M15: 0.84 | N15: 0.86 | O15: =AVERAGE(J15:N15) -> 0.846
B16: Index of Results
I17: Generate free relations | J17: 23.65 | K17: 23.68 | L17: 23.88 | M17: 23.58 | N17: 23.77 | O17: =AVERAGE(J17:N17) -> 23.712
I21: MurphyE of poly found: | J21: 1.06e-08 | K21: 9.93e-09 | L21: 9.89e-09 | M21: 8.73e-09 | N21: 9.95e-09 | O21: =AVERAGE(J21:N21) -> 9.82e-09
J23: Run
E24: Parameters | I24: Execution | J24: c100_1 | K24: c100_2 | L24: c100_3 | M24: c100_4 | N24: c100_5 | O24: Mean
D25: Lattice Sieving | E25: Primary: | G25: Job control: | I25: Lattice Sieving | J25: 6385.13 | K25: 7076.9 | L25: 7380.57 | M25: 76356.6 | N25: 70550.6 | O25: =AVERAGE(J25:N25) -> 33549.96
E26: mfb0 | F26: 49 | G26: qmin | H26: 1051872
E27: mfb1 | F27: 50 | G27: qrange | H27: 10000
E28: lambda0 | G28: threads
E29: lambda1
E30: ncurves0 | F30: 11
E31: ncurves1 | F31: 16
E32: sqside
E33: I | F33: 11
J36: Run
E37: Parameters | I37: Execution | J37: c100_1 | K37: c100_2 | L37: c100_3 | M37: c100_4 | N37: c100_5 | O37: Mean
D38: Filtering | E38: purge.keep | F38: 160 | I38: Duplicate Removal, splitting pass: | J38: 5.49 | K38: 5.74 | L38: 7.2 | M38: 5.76 | N38: 5.71 | O38: =AVERAGE(J38:N38) -> 5.98
E39: add_ratio | I39: Duplicate Removal, removal pass: | J39: 21.17 | K39: 22.1 | L39: 22.16 | M39: 21.3 | N39: 22.72 | O39: =AVERAGE(J39:N39) -> 21.89
E40: maxlevel | F40: 20 | I40: Singleton removal | J40: 18.66 | K40: 18.45 | L40: 19.66 | M40: 15.39 | N40: 19.46 | O40: =AVERAGE(J40:N40) -> 18.324
E41: target_density | F41: 170 | I41: Merging - merge | J41: 61.43 | K41: 66.62 | L41: 66.82 | M41: 83.91 | N41: 70.36 | O41: =AVERAGE(J41:N41) -> 69.828
E42: required_excess | I42: Merging - replay | J42: 6.76 | K42: 7.08 | L42: 7.06 | M42: 8.37 | N42: 7.47 | O42: =AVERAGE(J42:N42) -> 7.348
J45: Run
E46: Parameters | I46: Execution | J46: c100_1 | K46: c100_2 | L46: c100_3 | M46: c100_4 | N46: c100_5 | O46: Mean
D47: Linear Algebra | E47: Primary: | G47: Job control: | I47: Total | J47: 472 | K47: 570.97 | L47: 554.06 | M47: 733.04 | N47: 612.9 | O47: =AVERAGE(J47:N47) -> 588.594
E48: interval | F48: 1000 | G48: bwc.threads | I48: Quadratic | J48: 5.41 | K48: 5.64 | L48: 5.6 | M48: 6.58 | N48: 5.79 | O48: =AVERAGE(J48:N48) -> 5.804
E49: interleaving | F49: 0 | G49: characters.threads | I49: Square root | J49: 26.78 | K49: 27.11 | L49: 30.7 | M49: 32.84 | N49: 31.16 | O49: =AVERAGE(J49:N49) -> 29.718
E50: m | F50: 64
...

Sheet c105
B2: c105 | J2: Run
E3: Parameters | I3: Execution | J3: c105_1 | K3: c105_2 | L3: c105_3 | M3: c105_4 | N3: c105_5 | O3: Mean
B4: Prev | D4: Polynomial selection | E4: Primary: | G4: Job control: | I4: Size optimization | J4: 219.68 | K4: 222.98 | L4: 219.85 | M4: 220.01 | N4: 221.21 | O4: =AVERAGE(J4:N4) -> 220.746 | R4: =O4+O13 -> 369.99
E5: ad | G5: incr | H5: 60
B6: Contents | E6: - min: | F6: 0 | G6: ad
E7: - max: | F7: 500000 | G7: - range: | H7: 5000
B8: Next | E8: P | F8: 10000 | G8: threads
E9: sopteffort | F9: 0
B10: Index of Integers | E10: nq | F10: 256
E11: nrkeep | F11: 50
E12: degree | F12: 4
B13: Index of Parameters | E13: ropteffort | F13: 1 | I13: Root optimization | J13: 108.69 | K13: 308.11 | L13: 110.54 | M13: 109.6 | N13: 109.28 | O13: =AVERAGE(J13:N13) -> 149.244
I15: Generate factor base | J15: 0.97 | K15: 0.98 | L15: 0.96 | M15: 0.97 | N15: 0.98 | O15: =AVERAGE(J15:N15) -> 0.972
B16: Index of Results
I17: Generate free relations | J17: 12.07 | K17: 12.13 | L17: 12.08 | M17: 12.09 | N17: 12.06 | O17: =AVERAGE(J17:N17) -> 12.086
I21: MurphyE of poly found: | J21: 4.51e-09 | K21: 4.11e-09 | L21: 4.75e-09 | M21: 4.09e-09 | N21: 5.18e-09 | O21: =AVERAGE(J21:N21) -> 4.528e-09
J23: Run
E24: Parameters | I24: Execution | J24: c105_1 | K24: c105_2 | L24: c105_3 | M24: c105_4 | N24: c105_5 | O24: Mean
D25: Lattice Sieving | E25: Primary: | G25: Job control: | I25: Lattice Sieving | J25: 137139 | K25: 169752 | L25: 13488.8 | M25: 15635.7 | N25: 13978.8 | O25: =AVERAGE(J25:N25) -> 69998.86
E26: mfb0 | F26: 47 | G26: qmin | H26: 1536958
E27: mfb1 | F27: 52 | G27: qrange | H27: 5000
E28: lambda0 | G28: threads
E29: lambda1
E30: ncurves0 | F30: 14
E31: ncurves1 | F31: 4
E32: sqside
E33: I | F33: 11
J36: Run
E37: Parameters | I37: Execution | J37: c105_1 | K37: c105_2 | L37: c105_3 | M37: c105_4 | N37: c105_5 | O37: Mean
D38: Filtering | E38: purge.keep | F38: 160 | I38: Duplicate Removal, splitting pass: | J38: 5.11 | K38: 5.53 | L38: 4.84 | M38: 5.05 | N38: 4.99 | O38: =AVERAGE(J38:N38) -> 5.104
E39: add_ratio | I39: Duplicate Removal, removal pass: | J39: 29.16 | K39: 29.63 | L39: 27.07 | M39: 26.72 | N39: 26.52 | O39: =AVERAGE(J39:N39) -> 27.82
E40: maxlevel | F40: 20 | I40: Singleton removal | J40: 24.67 | K40: 24.26 | L40: 20.87 | M40: 21 | N40: 20.86 | O40: =AVERAGE(J40:N40) -> 22.332
E41: target_density | F41: 170 | I41: Merging - merge | J41: 111.6 | K41: 121.91 | L41: 111.96 | M41: 115.9 | N41: 114.06 | O41: =AVERAGE(J41:N41) -> 115.086
E42: required_excess | I42: Merging - replay | J42: 24.67 | K42: 11.84 | L42: 10.78 | M42: 11.24 | N42: 10.89 | O42: =AVERAGE(J42:N42) -> 13.884
J45: Run
E46: Parameters | I46: Execution | J46: c105_1 | K46: c105_2 | L46: c105_3 | M46: c105_4 | N46: c105_5 | O46: Mean
D47: Linear Algebra | E47: Primary: | G47: Job control: | I47: Total | J47: 1189.26 | K47: 1532.43 | L47: 1217.48 | M47: 1249.65 | N47: 1203.48 | O47: =AVERAGE(J47:N47) -> 1278.46
E48: interval | F48: 1000 | G48: bwc.threads | I48: Quadratic | J48: 8.19 | K48: 8.84 | L48: 8.36 | M48: 8.5 | N48: 8.45 | O48: =AVERAGE(J48:N48) -> 8.468
E49: interleaving | F49: 0 | G49: characters.threads | I49: Square root | J49: 47.11 | K49: 53.35 | L49: 45.38 | M49: 48.32 | N49: 45.82 | O49: =AVERAGE(J49:N49) -> 47.996
E50: m | F50: 64
...

Sheet c110
B2: c110 | J2: Run
E3: Parameters | I3: Execution | J3: c110_1 | K3: c110_2 | L3: c110_3 | M3: c110_4 | N3: c110_5 | O3: Mean
B4: Prev | D4: Polynomial selection | E4: Primary: | G4: Job control: | I4: Size optimization | J4: 1107.02 | K4: 1121.11 | L4: 1108.89 | M4: 1127.3 | N4: 1116.47 | O4: =AVERAGE(J4:N4) -> 1116.158 | R4: =O4+O13 -> 1463.864
E5: ad | G5: incr | H5: 60
B6: Contents | E6: - min: | F6: 0 | G6: ad
E7: - max: | F7: 500000 | G7: - range: | H7: 5000
B8: Next | E8: P | F8: 10000 | G8: threads
E9: sopteffort | F9: 0
B10: Index of Integers | E10: nq | F10: 625
E11: nrkeep | F11: 100
E12: degree | F12: 5
B13: Index of Parameters | E13: ropteffort | F13: 1 | I13: Root optimization | J13: 365.63 | K13: 344.93 | L13: 361.77 | M13: 321.52 | N13: 344.68 | O13: =AVERAGE(J13:N13) -> 347.706
I15: Generate factor base | J15: 3.65 | K15: 3.69 | L15: 3.65 | M15: 3.68 | N15: 3.63 | O15: =AVERAGE(J15:N15) -> 3.66
B16: Index of Results
I17: Generate free relations | J17: 31.88 | K17: 31.87 | L17: 31.98 | M17: 32.12 | N17: 31.75 | O17: =AVERAGE(J17:N17) -> 31.92
I21: MurphyE of poly found: | J21: 4.94e-09 | K21: 5.1e-09 | L21: 5.25e-09 | M21: 4.93e-09 | N21: 4.82e-09 | O21: =AVERAGE(J21:N21) -> 5.008e-09
J23: Run
E24: Parameters | I24: Execution | J24: c30_1 | K24: c30_2 | L24: c30_3 | M24: c30_4 | N24: c30_5 | O24: Mean
D25: Lattice Sieving | E25: Primary: | G25: Job control: | I25: Lattice Sieving | J25: 28310.9 | K25: 23986.3 | L25: 27185.1 | M25: 26488.5 | N25: 26758.2 | O25: =AVERAGE(J25:N25) -> 26545.8
E26: mfb0 | F26: 55 | G26: qmin | H26: 971708
E27: mfb1 | F27: 51 | G27: qrange | H27: 10000
E28: lambda0 | G28: threads
E29: lambda1
E30: ncurves0 | F30: 10
E31: ncurves1 | F31: 17
E32: sqside
E33: I | F33: 12
J36: Run
E37: Parameters | I37: Execution | J37: c30_1 | K37: c30_2 | L37: c30_3 | M37: c30_4 | N37: c30_5 | O37: Mean
D38: Filtering | E38: purge.keep | F38: 160 | I38: Duplicate Removal, splitting pass: | J38: 8.44 | K38: 8.13 | L38: 8.3 | M38: 8.21 | N38: 8.39 | O38: =AVERAGE(J38:N38) -> 8.294
E39: add_ratio | I39: Duplicate Removal, removal pass: | J39: 49.25 | K39: 38.53 | L39: 39.74 | M39: 39.04 | N39: 40.21 | O39: =AVERAGE(J39:N39) -> 41.354
E40: maxlevel | F40: 20 | I40: Singleton removal | J40: 36.71 | K40: 25.88 | L40: 24.14 | M40: 22.79 | N40: 27.76 | O40: =AVERAGE(J40:N40) -> 27.456
E41: target_density | F41: 170 | I41: Merging - merge | J41: 149.61 | K41: 129.69 | L41: 148.5 | M41: 154.72 | N41: 126.66 | O41: =AVERAGE(J41:N41) -> 141.836
E42: required_excess | I42: Merging - replay | J42: 15.2 | K42: 13.34 | L42: 15.13 | M42: 15.56 | N42: 13.35 | O42: =AVERAGE(J42:N42) -> 14.516
J45: Run
E46: Parameters | I46: Execution | J46: c30_1 | K46: c30_2 | L46: c30_3 | M46: c30_4 | N46: c30_5 | O46: Mean
D47: Linear Algebra | E47: Primary: | G47: Job control: | I47: Total | J47: 2275.19 | K47: 1551.45 | L47: 2066.71 | M47: 2325.43 | N47: 1762.61 | O47: =AVERAGE(J47:N47) -> 1996.278
E48: interval | F48: 1000 | G48: bwc.threads | I48: Quadratic | J48: 12.23 | K48: 10.84 | L48: 12.3 | M48: 12.46 | N48: 10.89 | O48: =AVERAGE(J48:N48) -> 11.744
E49: interleaving | F49: 0 | G49: characters.threads | I49: Square root | J49: 90.24 | K49: 77.31 | L49: 80.59 | M49: 81.74 | N49: 258.84 | O49: =AVERAGE(J49:N49) -> 117.744
E50: m | F50: 64
...

Sheet c115
B2: c115 | J2: Run
E3: Parameters | I3: Execution | J3: c115_1 | K3: c115_2 | L3: c115_3 | M3: c115_4 | N3: c115_5 | O3: Mean
B4: Prev | D4: Polynomial selection | E4: Primary: | G4: Job control: | I4: Size optimization | J4: 1103.87 | K4: 1104.3 | L4: 1104.61 | M4: 1102.84 | N4: 1105.23 | O4: =AVERAGE(J4:N4) -> 1104.17
E5: ad | G5: incr | H5: 60
B6: Contents | E6: - min: | F6: 0 | G6: ad
E7: - max: | F7: 1000000 | G7: - range: | H7: 10000
B8: Next | E8: P | F8: 10000 | G8: threads
E9: sopteffort | F9: 0
B10: Index of Integers | E10: nq | F10: 625
E11: nrkeep | F11: 100
E12: degree | F12: 4
B13: Index of Parameters | E13: ropteffort | F13: 1 | I13: Root optimization | J13: 220.29 | K13: 224.77 | L13: 224.64 | M13: 218.37 | N13: 220.48 | O13: =AVERAGE(J13:N13) -> 221.71
I15: Generate factor base | O15: =AVERAGE(J15:N15) -> #DIV/0!
B16: Index of Results
I17: Generate free relations | O17: =AVERAGE(J17:N17) -> #DIV/0!
I21: MurphyE of poly found: | J21: 2.11e-09 | K21: 2.07e-09 | L21: 2.09e-09 | M21: 2e-09 | N21: 2.12e-09 | O21: =AVERAGE(J21:N21) -> 2.078e-09
J23: Run
E24: Parameters | I24: Execution | J24: c115_1 | K24: c115_2 | L24: c115_3 | M24: c115_4 | N24: c115_5 | O24: Mean
D25: Lattice Sieving | E25: Primary: | G25: Job control: | I25: Lattice Sieving | O25: =AVERAGE(J25:N25) -> #DIV/0!
E26: mfb0 | F26: 67 | G26: qmin | H26: 2500740
E27: mfb1 | F27: 51 | G27: qrange | H27: 2000
E28: lambda0 | G28: threads
E29: lambda1
E30: ncurves0 | F30: 8
E31: ncurves1 | F31: 11
E32: sqside
E33: I | F33: 13
J36: Run
E37: Parameters | I37: Execution | J37: c115_1 | K37: c115_2 | L37: c115_3 | M37: c115_4 | N37: c115_5 | O37: Mean
D38: Filtering | E38: purge.keep | F38: 160 | I38: Duplicate Removal, splitting pass: | O38: =AVERAGE(J38:N38) -> #DIV/0!
E39: add_ratio | I39: Duplicate Removal, removal pass: | O39: =AVERAGE(J39:N39) -> #DIV/0!
E40: maxlevel | F40: 20 | I40: Singleton removal | O40: =AVERAGE(J40:N40) -> #DIV/0!
E41: target_density | F41: 170 | I41: Merging - merge | O41: =AVERAGE(J41:N41) -> #DIV/0!
E42: required_excess | I42: Merging - replay | O42: =AVERAGE(J42:N42) -> #DIV/0!
J45: Run
E46: Parameters | I46: Execution | J46: c115_1 | K46: c115_2 | L46: c115_3 | M46: c115_4 | N46: c115_5 | O46: Mean
D47: Linear Algebra | E47: Primary: | G47: Job control: | I47: Total | O47: =AVERAGE(J47:N47) -> #DIV/0!
E48: interval | F48: 1000 | G48: bwc.threads | I48: Quadratic | O48: =AVERAGE(J48:N48) -> #DIV/0!
E49: interleaving | F49: 0 | G49: characters.threads | I49: Square root | O49: =AVERAGE(J49:N49) -> #DIV/0!
E50: m | F50: 64
...

Sheet c120
B2: c120 | J2: Run
E3: Parameters | I3: Execution | J3: c120_1 | K3: c120_2 | L3: c120_3 | M3: c120_4 | N3: c120_5 | O3: Mean
B4: Prev | D4: Polynomial selection | E4: Primary: | G4: Job control: | I4: Size optimization | J4: 1316.48 | K4: 1331.2 | L4: 1315.81 | M4: 1320.25 | N4: 1330.13 | O4: =AVERAGE(J4:N4) -> 1322.774
E5: ad | G5: incr | H5: 60
B6: Contents | E6: - min: | F6: 0 | G6: ad
E7: - max: | F7: 50000 | G7: - range: | H7: 500
B8: Next | E8: P | F8: 50000 | G8: threads
E9: sopteffort | F9: 0
B10: Index of Integers | E10: nq | F10: 3125
E11: nrkeep | F11: 100
E12: degree | F12: 5
B13: Index of Parameters | E13: ropteffort | F13: 1 | I13: Root optimization | J13: 618.4 | K13: 525.8 | L13: 534.11 | M13: 476.68 | N13: 535.84 | O13: =AVERAGE(J13:N13) -> 538.166
I15: Generate factor base | O15: =AVERAGE(J15:N15) -> #DIV/0!
B16: Index of Results
I17: Generate free relations | O17: =AVERAGE(J17:N17) -> #DIV/0!
I21: MurphyE of poly found: | J21: 1.69e-09 | K21: 1.83e-09 | L21: 1.74e-09 | M21: 1.87e-09 | N21: 1.87e-09 | O21: =AVERAGE(J21:N21) -> 1.8e-09
J23: Run
E24: Parameters | I24: Execution | J24: c120_1 | K24: c120_2 | L24: c120_3 | M24: c120_4 | N24: c120_5 | O24: Mean
D25: Lattice Sieving | E25: Primary: | G25: Job control: | I25: Lattice Sieving | O25: =AVERAGE(J25:N25) -> #DIV/0!
E26: mfb0 | F26: 52 | G26: qmin | H26: 148735
E27: mfb1 | F27: 54 | G27: qrange | H27: 1000
E28: lambda0 | G28: threads
E29: lambda1
E30: ncurves0 | F30: 10
E31: ncurves1 | F31: 22
E32: sqside
E33: I | F33: 14
J36: Run
E37: Parameters | I37: Execution | J37: c120_1 | K37: c120_2 | L37: c120_3 | M37: c120_4 | N37: c120_5 | O37: Mean
D38: Filtering | E38: purge.keep | F38: 160 | I38: Duplicate Removal, splitting pass: | O38: =AVERAGE(J38:N38) -> #DIV/0!
E39: add_ratio | I39: Duplicate Removal, removal pass: | O39: =AVERAGE(J39:N39) -> #DIV/0!
E40: maxlevel | F40: 25 | I40: Singleton removal | O40: =AVERAGE(J40:N40) -> #DIV/0!
E41: target_density | F41: 170 | I41: Merging - merge | O41: =AVERAGE(J41:N41) -> #DIV/0!
E42: required_excess | I42: Merging - replay | O42: =AVERAGE(J42:N42) -> #DIV/0!
J45: Run
E46: Parameters | I46: Execution | J46: c120_1 | K46: c120_2 | L46: c120_3 | M46: c120_4 | N46: c120_5 | O46: Mean
D47: Linear Algebra | E47: Primary: | G47: Job control: | I47: Total | O47: =AVERAGE(J47:N47) -> #DIV/0!
E48: interval | F48: 1000 | G48: bwc.threads | I48: Quadratic | O48: =AVERAGE(J48:N48) -> #DIV/0!
E49: interleaving | F49: 0 | G49: characters.threads | I49: Square root | O49: =AVERAGE(J49:N49) -> #DIV/0!
E50: m | F50: 64
...

Sheet c125
B2: c125 | J2: Run
E3: Parameters | I3: Execution | J3: c125_1 | K3: c125_2 | L3: c125_3 | M3: c125_4 | N3: c125_5 | O3: Mean
B4: Prev | D4: Polynomial selection | E4: Primary: | G4: Job control: | I4: Size optimization | J4: 1996.27 | K4: 1995.75 | L4: 1982.31 | M4: 1992.45 | N4: 1980.31 | O4: =AVERAGE(J4:N4) -> 1989.418
E5: ad | G5: incr | H5: 60
B6: Contents | E6: - min: | F6: 0 | G6: ad
E7: - max: | F7: 500000 | G7: - range: | H7: 5000
B8: Next | E8: P | F8: 40000 | G8: threads
E9: sopteffort | F9: 0
B10: Index of Integers | E10: nq | F10: 625
E11: nrkeep | F11: 100
E12: degree | F12: 5
B13: Index of Parameters | E13: ropteffort | F13: 5 | I13: Root optimization | J13: 1562.31 | K13: 1411.18 | L13: 1379.42 | M13: 1432.34 | N13: 1287.52 | O13: =AVERAGE(J13:N13) -> 1414.554
I15: Generate factor base | O15: =AVERAGE(J15:N15) -> #DIV/0!
B16: Index of Results
I17: Generate free relations | O17: =AVERAGE(J17:N17) -> #DIV/0!
I21: MurphyE of poly found: | J21: 6.6e-10 | K21: 6.59e-10 | L21: 6.23e-10 | M21: 6.34e-10 | N21: 5.96e-10 | O21: =AVERAGE(J21:N21) -> 6.344e-10
J23: Run
E24: Parameters | I24: Execution | J24: c125_1 | K24: c125_2 | L24: c125_3 | M24: c125_4 | N24: c125_5 | O24: Mean
D25: Lattice Sieving | E25: Primary: | G25: Job control: | I25: Lattice Sieving | O25: =AVERAGE(J25:N25) -> #DIV/0!
E26: mfb0 | F26: 57 | G26: qmin | H26: 3683755
E27: mfb1 | F27: 53 | G27: qrange | H27: 5000
E28: lambda0 | G28: threads
E29: lambda1
E30: ncurves0 | F30: 14
E31: ncurves1 | F31: 16
E32: sqside
E33: I | F33: 13
J36: Run
E37: Parameters | I37: Execution | J37: c125_1 | K37: c125_2 | L37: c125_3 | M37: c125_4 | N37: c125_5 | O37: Mean
D38: Filtering | E38: purge.keep | F38: 160 | I38: Duplicate Removal, splitting pass: | O38: =AVERAGE(J38:N38) -> #DIV/0!
E39: add_ratio | I39: Duplicate Removal, removal pass: | O39: =AVERAGE(J39:N39) -> #DIV/0!
E40: maxlevel | F40: 25 | I40: Singleton removal | O40: =AVERAGE(J40:N40) -> #DIV/0!
E41: target_density | F41: 170 | I41: Merging - merge | O41: =AVERAGE(J41:N41) -> #DIV/0!
E42: required_excess | I42: Merging - replay | O42: =AVERAGE(J42:N42) -> #DIV/0!
J45: Run
E46: Parameters | I46: Execution | J46: c125_1 | K46: c125_2 | L46: c125_3 | M46: c125_4 | N46: c125_5 | O46: Mean
D47: Linear Algebra | E47: Primary: | G47: Job control: | I47: Total | O47: =AVERAGE(J47:N47) -> #DIV/0!
E48: interval | F48: 1000 | G48: bwc.threads | I48: Quadratic | O48: =AVERAGE(J48:N48) -> #DIV/0!
E49: interleaving | F49: 0 | G49: characters.threads | I49: Square root | O49: =AVERAGE(J49:N49) -> #DIV/0!
E50: m | F50: 64
...

Sheet c130
B2: c130 | J2: Run
E3: Parameters | I3: Execution | J3: c130_1 | K3: c130_2 | L3: c130_3 | M3: c130_4 | N3: c130_5 | O3: Mean
B4: Prev | D4: Polynomial selection | E4: Primary: | G4: Job control: | I4: Size optimization | J4: 6584.45 | K4: 6581.91 | L4: 6579.25 | M4: 6554.15 | N4: 6558.47 | O4: =AVERAGE(J4:N4) -> 6571.646
E5: ad | G5: incr | H5: 60
B6: Contents | E6: - min: | F6: 0 | G6: ad
E7: - max: | F7: 1000000 | G7: - range: | H7: 10000
B8: Next | E8: P | F8: 80000 | G8: threads
E9: sopteffort | F9: 0
B10: Index of Integers | E10: nq | F10: 625
E11: nrkeep | F11: 100
E12: degree | F12: 5
B13: Index of Parameters | E13: ropteffort | F13: 10 | I13: Root optimization | J13: 2883.18 | K13: 2578.34 | L13: 2621.38 | M13: 2974.73 | N13: 2548.76 | O13: =AVERAGE(J13:N13) -> 2721.278
I15: Generate factor base | O15: =AVERAGE(J15:N15) -> #DIV/0!
B16: Index of Results
I17: Generate free relations | O17: =AVERAGE(J17:N17) -> #DIV/0!
I21: MurphyE of poly found: | J21: 1.74e-09 | K21: 1.73e-09 | L21: 1.77e-09 | M21: 1.72e-09 | N21: 1.75e-09 | O21: =AVERAGE(J21:N21) -> 1.742e-09
J23: Run
E24: Parameters | I24: Execution | J24: c130_1 | K24: c130_2 | L24: c130_3 | M24: c130_4 | N24: c130_5 | O24: Mean
D25: Lattice Sieving | E25: Primary: | G25: Job control: | I25: Lattice Sieving | O25: =AVERAGE(J25:N25) -> #DIV/0!
E26: mfb0 | F26: 55 | G26: qmin | H26: 1422541
E27: mfb1 | F27: 56 | G27: qrange | H27: 10000
E28: lambda0 | G28: threads
E29: lambda1
E30: ncurves0 | F30: 13
E31: ncurves1 | F31: 21
E32: sqside
E33: I | F33: 14
J36: Run
E37: Parameters | I37: Execution | J37: c130_1 | K37: c130_2 | L37: c130_3 | M37: c130_4 | N37: c130_5 | O37: Mean
D38: Filtering | E38: purge.keep | F38: 160 | I38: Duplicate Removal, splitting pass: | O38: =AVERAGE(J38:N38) -> #DIV/0!
E39: add_ratio | I39: Duplicate Removal, removal pass: | O39: =AVERAGE(J39:N39) -> #DIV/0!
E40: maxlevel | F40: 25 | I40: Singleton removal | O40: =AVERAGE(J40:N40) -> #DIV/0!
E41: target_density | F41: 170 | I41: Merging - merge | O41: =AVERAGE(J41:N41) -> #DIV/0!
E42: required_excess | I42: Merging - replay | O42: =AVERAGE(J42:N42) -> #DIV/0!
J45: Run
E46: Parameters | I46: Execution | J46: c130_1 | K46: c130_2 | L46: c130_3 | M46: c130_4 | N46: c130_5 | O46: Mean
D47: Linear Algebra | E47: Primary: | G47: Job control: | I47: Total | O47: =AVERAGE(J47:N47) -> #DIV/0!
E48: interval | F48: 1000 | G48: bwc.threads | I48: Quadratic | O48: =AVERAGE(J48:N48) -> #DIV/0!
E49: interleaving | F49: 0 | G49: characters.threads | I49: Square root | O49: =AVERAGE(J49:N49) -> #DIV/0!
E50: m | F50: 64
...

Sheet c135
B2: c135 | J2: Run
E3: Parameters | I3: Execution | J3: c135_1 | K3: c135_2 | L3: c135_3 | M3: c135_4 | N3: c135_5 | O3: Mean
B4: Prev | D4: Polynomial selection | E4: Primary: | G4: Job control: | I4: Size optimization | J4: 9903.98 | K4: 9972.08 | L4: 9944.23 | M4: 9954.42 | N4: 9898.02 | O4: =AVERAGE(J4:N4) -> 9934.546
E5: ad | G5: incr | H5: 60
B6: Contents | E6: - min: | F6: 0 | G6: ad
E7: - max: | F7: 200000 | G7: - range: | H7: 2000
B8: Next | E8: P | F8: 120000 | G8: threads
E9: sopteffort | F9: 0
B10: Index of Integers | E10: nq | F10: 3125
E11: nrkeep | F11: 100
E12: degree | F12: 5
B13: Index of Parameters | E13: ropteffort | F13: 10 | I13: Root optimization | J13: 3475.56 | K13: 3563.62 | L13: 3784.58 | M13: 3851.44 | N13: 3204.37 | O13: =AVERAGE(J13:N13) -> 3575.914
I15: Generate factor base | O15: =AVERAGE(J15:N15) -> #DIV/0!
B16: Index of Results
I17: Generate free relations | O17: =AVERAGE(J17:N17) -> #DIV/0!
I21: MurphyE of poly found: | J21: 3.61e-10 | K21: 4.35e-10 | L21: 3.54e-10 | M21: 4.28e-10 | N21: 3.68e-10 | O21: =AVERAGE(J21:N21) -> 3.892e-10
J23: Run
E24: Parameters | I24: Execution | J24: c135_1 | K24: c135_2 | L24: c135_3 | M24: c135_4 | N24: c135_5 | O24: Mean
D25: Lattice Sieving | E25: Primary: | G25: Job control: | I25: Lattice Sieving | O25: =AVERAGE(J25:N25) -> #DIV/0!
E26: mfb0 | F26: 51 | G26: qmin | H26: 10664570
E27: mfb1 | F27: 62 | G27: qrange | H27: 10000
E28: lambda0 | G28: threads
E29: lambda1
E30: ncurves0 | F30: 12
E31: ncurves1 | F31: 13
E32: sqside
E33: I | F33: 13
J36: Run
E37: Parameters | I37: Execution | J37: c135_1 | K37: c135_2 | L37: c135_3 | M37: c135_4 | N37: c135_5 | O37: Mean
D38: Filtering | E38: purge.keep | F38: 160 | I38: Duplicate Removal, splitting pass: | O38: =AVERAGE(J38:N38) -> #DIV/0!
E39: add_ratio | I39: Duplicate Removal, removal pass: | O39: =AVERAGE(J39:N39) -> #DIV/0!
E40: maxlevel | F40: 25 | I40: Singleton removal | O40: =AVERAGE(J40:N40) -> #DIV/0!
E41: target_density | F41: 170 | I41: Merging - merge | O41: =AVERAGE(J41:N41) -> #DIV/0!
E42: required_excess | I42: Merging - replay | O42: =AVERAGE(J42:N42) -> #DIV/0!
J45: Run
E46: Parameters | I46: Execution | J46: c135_1 | K46: c135_2 | L46: c135_3 | M46: c135_4 | N46: c135_5 | O46: Mean
D47: Linear Algebra | E47: Primary: | G47: Job control: | I47: Total | O47: =AVERAGE(J47:N47) -> #DIV/0!
E48: interval | F48: 1000 | G48: bwc.threads | I48: Quadratic | O48: =AVERAGE(J48:N48) -> #DIV/0!
E49: interleaving | F49: 0 | G49: characters.threads | I49: Square root | O49: =AVERAGE(J49:N49) -> #DIV/0!
E50: m | F50: 64
...

Sheet c140
B2: c140 | J2: Run
E3: Parameters | I3: Execution | J3: c140_1 | K3: c140_2 | L3: c140_3 | M3: c140_4 | N3: c140_5 | O3: Mean
B4: Prev | D4: Polynomial selection | E4: Primary: | G4: Job control: | I4: Size optimization | J4: 31126.3 | K4: 31068.7 | L4: 31108.8 | M4: 31196.4 | N4: 31019.9 | O4: =AVERAGE(J4:N4) -> 31104.02
E5: ad | G5: incr | H5: 60
B6: Contents | E6: - min: | F6: 0 | G6: ad
E7: - max: | F7: 400000 | G7: - range: | H7: 4000
B8: Next | E8: P | F8: 200000 | G8: threads
E9: sopteffort | F9: 0
B10: Index of Integers | E10: nq | F10: 3125
E11: nrkeep | F11: 100
E12: degree | F12: 5
B13: Index of Parameters | E13: ropteffort | F13: 10 | I13: Root optimization | J13: 4182.29 | K13: 4645.5 | L13: 4169.85 | M13: 4608.42 | N13: 3654.52 | O13: =AVERAGE(J13:N13) -> 4252.116
I15: Generate factor base | O15: =AVERAGE(J15:N15) -> #DIV/0!
B16: Index of Results
I17: Generate free relations | O17: =AVERAGE(J17:N17) -> #DIV/0!
I21: MurphyE of poly found: | J21: 8.53e-10 | K21: 8.93e-10 | L21: 8.32e-10 | M21: 7.94e-10 | N21: 9.11e-10 | O21: =AVERAGE(J21:N21) -> 8.566e-10
J23: Run
E24: Parameters | I24: Execution | J24: c140_1 | K24: c140_2 | L24: c140_3 | M24: c140_4 | N24: c140_5 | O24: Mean
D25: Lattice Sieving | E25: Primary: | G25: Job control: | I25: Lattice Sieving | O25: =AVERAGE(J25:N25) -> #DIV/0!
E26: mfb0 | F26: 62 | G26: qmin
E27: mfb1 | F27: 61 | G27: qrange | H27: 10000
E28: lambda0 | F28: 2.1 | G28: threads
E29: lambda1 | F29: 2.29
E30: ncurves0 | F30: 10
E31: ncurves1 | F31: 13
E32: sqside
E33: I | F33: 13
J36: Run
E37: Parameters | I37: Execution | J37: c140_1 | K37: c140_2 | L37: c140_3 | M37: c140_4 | N37: c140_5 | O37: Mean
D38: Filtering | E38: purge.keep | F38: 160 | I38: Duplicate Removal, splitting pass: | O38: =AVERAGE(J38:N38) -> #DIV/0!
E39: add_ratio | I39: Duplicate Removal, removal pass: | O39: =AVERAGE(J39:N39) -> #DIV/0!
E40: maxlevel | F40: 25 | I40: Singleton removal | O40: =AVERAGE(J40:N40) -> #DIV/0!
E41: target_density | F41: 170 | I41: Merging - merge | O41: =AVERAGE(J41:N41) -> #DIV/0!
E42: required_excess | I42: Merging - replay | O42: =AVERAGE(J42:N42) -> #DIV/0!
J45: Run
E46: Parameters | I46: Execution | J46: c140_1 | K46: c140_2 | L46: c140_3 | M46: c140_4 | N46: c140_5 | O46: Mean
D47: Linear Algebra | E47: Primary: | G47: Job control: | I47: Total | O47: =AVERAGE(J47:N47) -> #DIV/0!
E48: interval | F48: 1000 | G48: bwc.threads | I48: Quadratic | O48: =AVERAGE(J48:N48) -> #DIV/0!
E49: interleaving | F49: 0 | G49: characters.threads | I49: Square root | O49: =AVERAGE(J49:N49) -> #DIV/0!
E50: m | F50: 64
...

Sheet c145
B2: c145 | J2: Run
E3: Parameters | I3: Execution | J3: c145_1 | K3: c145_2 | L3: c145_3 | M3: c145_4 | N3: c145_5 | O3: Mean
B4: Prev | D4: Polynomial selection | E4: Primary: | G4: Job control: | I4: Size optimization | J4: 55451.1 | K4: 55205.3 | L4: 55266.6 | M4: 55250.3 | N4: 55090.8 | O4: =AVERAGE(J4:N4) -> 55252.82
E5: ad | G5: incr | H5: 60
B6: Contents | E6: - min: | F6: 0 | G6: ad
E7: - max: | F7: 500000 | G7: - range: | H7: 1000
B8: Next | E8: P | F8: 300000 | G8: threads
E9: sopteffort | F9: 0
B10: Index of Integers | E10: nq | F10: 3125
E11: nrkeep | F11: 100
E12: degree | F12: 5
B13: Index of Parameters | E13: ropteffort | I13: Root optimization | J13: 2641.04 | K13: 2782.15 | L13: 2764.7 | M13: 2399.85 | N13: 2117.79 | O13: =AVERAGE(J13:N13) -> 2541.106
I15: Generate factor base | O15: =AVERAGE(J15:N15) -> #DIV/0!
B16: Index of Results
I17: Generate free relations | O17: =AVERAGE(J17:N17) -> #DIV/0!
I21: MurphyE of poly found: | J21: 3e-10 | K21: 3.02e-10 | L21: 2.8e-10 | M21: 2.94e-10 | N21: 3.14e-10 | O21: =AVERAGE(J21:N21) -> 2.98e-10
J23: Run
E24: Parameters | I24: Execution | J24: c145_1 | K24: c145_2 | L24: c145_3 | M24: c145_4 | N24: c145_5 | O24: Mean
D25: Lattice Sieving | E25: Primary: | G25: Job control: | I25: Lattice Sieving | O25: =AVERAGE(J25:N25) -> #DIV/0!
E26: mfb0 | F26: 58 | G26: qmin
E27: mfb1 | F27: 87 | G27: qrange
E28: lambda0 | G28: threads
E29: lambda1
E30: ncurves0
E31: ncurves1
E32: sqside
E33: I | F33: 13
J36: Run
E37: Parameters | I37: Execution | J37: c145_1 | K37: c145_2 | L37: c145_3 | M37: c145_4 | N37: c145_5 | O37: Mean
D38: Filtering | E38: purge.keep | F38: 160 | I38: Duplicate Removal, splitting pass: | O38: =AVERAGE(J38:N38) -> #DIV/0!
E39: add_ratio | I39: Duplicate Removal, removal pass: | O39: =AVERAGE(J39:N39) -> #DIV/0!
E40: maxlevel | F40: 25 | I40: Singleton removal | O40: =AVERAGE(J40:N40) -> #DIV/0!
E41: target_density | F41: 170 | I41: Merging - merge | O41: =AVERAGE(J41:N41) -> #DIV/0!
E42: required_excess | I42: Merging - replay | O42: =AVERAGE(J42:N42) -> #DIV/0!
J45: Run
E46: Parameters | I46: Execution | J46: c145_1 | K46: c145_2 | L46: c145_3 | M46: c145_4 | N46: c145_5 | O46: Mean
D47: Linear Algebra | E47: Primary: | G47: Job control: | I47: Total | O47: =AVERAGE(J47:N47) -> #DIV/0!
E48: interval | F48: 1000 | G48: bwc.threads | I48: Quadratic | O48: =AVERAGE(J48:N48) -> #DIV/0!
E49: interleaving | F49: 0 | G49: characters.threads | I49: Square root | O49: =AVERAGE(J49:N49) -> #DIV/0!
E50: m | F50: 64
...

Sheet c150
B2: c150 | J2: Run
E3: Parameters | I3: Execution | J3: c150_1 | K3: c150_2 | L3: c150_3 | M3: c150_4 | N3: c150_5 | O3: Mean
B4: Prev | D4: Polynomial selection | E4: Primary: | G4: Job control: | I4: Size optimization | J4: 70775.9 | K4: 71260.2 | L4: 71232.6 | M4: 56931.6 | N4: 71111.9 | O4: =AVERAGE(J4:N4) -> 68262.44
E5: ad | G5: incr | H5: 60
B6: Contents | E6: - min: | F6: 0 | G6: ad
E7: - max: | F7: 400000 | G7: - range: | H7: 1000
B8: Next | E8: P | F8: 500000 | G8: threads
E9: sopteffort | F9: 0
B10: Index of Integers | E10: nq | F10: 3125
E11: nrkeep | F11: 100
E12: degree | F12: 5
B13: Index of Parameters | E13: ropteffort | F13: 10 | I13: Root optimization | J13: 6846.1 | K13: 7087.51 | L13: 6450.86 | M13: 7501.06 | N13: 6154.67 | O13: =AVERAGE(J13:N13) -> 6808.04
I15: Generate factor base | O15: =AVERAGE(J15:N15) -> #DIV/0!
B16: Index of Results
I17: Generate free relations | O17: =AVERAGE(J17:N17) -> #DIV/0!
I21: MurphyE of poly found: | J21: 3.46e-10 | K21: 3.51e-10 | L21: 3.68e-10 | M21: 3.22e-10 | N21: 3.54e-10 | O21: =AVERAGE(J21:N21) -> 3.482e-10
I23: Wall clock (seconds): | J23: n/a | K23: n/a | L23: n/a | M23: 2454.831 | N23: 2380.834 | O23: =AVERAGE(J23:N23) -> 2417.8325
J25: Run
E26: Parameters | I26: Execution | J26: c150_1 | K26: c150_2 | L26: c150_3 | M26: c150_4 | N26: c150_5 | O26: Mean
D27: Lattice Sieving | E27: Primary: | G27: Job control: | I27: Lattice Sieving | O27: =AVERAGE(J27:N27) -> #DIV/0!
E28: mfb0 | F28: 64 | G28: qmin
E29: mfb1 | F29: 87 | G29: qrange | H29: 10000
E30: lambda0 | G30: threads
E31: lambda1
E32: ncurves0 | F32: 12
E33: ncurves1 | F33: 10
E34: sqside
E35: I | F35: 13
J38: Run
E39: Parameters | I39: Execution | J39: c150_1 | K39: c150_2 | L39: c150_3 | M39: c150_4 | N39: c150_5 | O39: Mean
D40: Filtering | E40: purge.keep | F40: 160 | I40: Duplicate Removal, splitting pass: | O40: =AVERAGE(J40:N40) -> #DIV/0!
E41: add_ratio | I41: Duplicate Removal, removal pass: | O41: =AVERAGE(J41:N41) -> #DIV/0!
E42: maxlevel | F42: 30 | I42: Singleton removal | O42: =AVERAGE(J42:N42) -> #DIV/0!
E43: target_density | F43: 170 | I43: Merging - merge | O43: =AVERAGE(J43:N43) -> #DIV/0!
E44: required_excess | I44: Merging - replay | O44: =AVERAGE(J44:N44) -> #DIV/0!
J47: Run
E48: Parameters | I48: Execution | J48: c150_1 | K48: c150_2 | L48: c150_3 | M48: c150_4 | N48: c150_5 | O48: Mean
D49: Linear Algebra | E49: Primary: | G49: Job control: | I49: Total | O49: =AVERAGE(J49:N49) -> #DIV/0!
E50: interval | F50: 1000 | G50: bwc.threads | I50: Quadratic | O50: =AVERAGE(J50:N50) -> #DIV/0!
